Workbook

Sheet MASTER_TC
A1: TC ID | B1: Hari | C1: Modul | D1: Fitur | E1: Jenis Uji | F1: Prioritas | G1: Prasyarat | H1: Langkah Uji | I1: Expected Result | J1: Actual Result | K1: Status | L1: Severity | M1: Bug ID | N1: Bukti | O1: Penguji | P1: Tanggal Uji | Q1: Commit/Build | R1: Catatan
A2: TC-API-001 | C2: API | D2: GET List Assets | E2: Normal | F2: P1 | G2: Backend jalan, Postman siap | H2: 1. Buka Postman 2. Kirim GET /api/assets 3. Amati response | I2: HTTP 200, list aset tampil | J2: 200 OK, data 17 aset tampil di database | K2: PASS | L2: 15/10/2026 | O2: Reza Tri | P2: 17/10/2026 | R2: Aset bertambah dari 16 menjadi 17, sistem normal
A3: TC-API-002 | B3: 8 | C3: API | D3: GET Detail Asset | E3: Normal | F3: P1 | I3: HTTP 200, detail aset tampil | J3: 200 OK, detail aset tampil | K3: PASS | L3: 15/10/2026 | O3: Reza Tri | P3: 13/10/2026 | R3: Test di Postman, backend jalan
A4: TC-API-003 | B4: 8 | C4: API | D4: POST Create Asset | E4: Normal | F4: P1 | G4: anji | I4: HTTP 201, aset tersimpan | J4: 201 Created, aset tersimpan | K4: PASS | L4: 15/10/2026 | O4: Reza Tri
A5: TC-API-004 | B5: 8 | C5: API | D5: POST tanpa field wajib | E5: Negatif | F5: P1 | I5: HTTP 400, error jelas | J5: 400 Bad Request, validasi jalan | K5: PASS | L5: 15/10/2026 | O5: Reza Tri
A6: TC-API-005 | B6: 8 | C6: API | D6: GET ID tidak ada | E6: Negatif | F6: P1 | I6: HTTP 404, error jelas | J6: 404 Not Found, error jelas | K6: PASS | L6: 15/10/2026 | O6: Reza Tri
A7: TC-API-006 | B7: 9 | C7: API | D7: PUT Update Asset | E7: Normal | F7: P1 | I7: HTTP 200, data terupdate | J7: 200 OK, data terupdate | K7: PASS | L7: 15/10/2026 | O7: Reza Tri | P7: hyfxxdddd
A8: TC-API-007 | B8: 9 | C8: API | D8: DELETE Asset | E8: Normal | F8: P1 | I8: HTTP 200, aset terhapus | J8: 200 OK, aset terhapus | K8: PASS | L8: 15/10/2026 | O8: Reza Tri
A9: TC-API-008 | B9: 9 | C9: API | D9: Validasi IP Address | E9: Boundary | F9: P2 | I9: HTTP 400, error jelas | J9: 400 Bad Request, error jelas | K9: PASS | L9: 15/10/2026 | O9: Reza Tri
A10: TC-API-009 | B10: 9 | C10: API | D10: Duplikasi Asset Code | E10: Negatif | F10: P1 | I10: HTTP 409, error duplicate | J10: 409 Conflict, duplikat terdeteksi | K10: PASS | L10: 15/10/2026 | O10: Reza Tri | R10: Test di Postman, backend jalan
A11: TC-API-010 | B11: 9 | C11: API | D11: Response time < 2 detik | E11: Boundary | F11: P2 | G11: Postman siap, backend jalan, token valid | H11: 1. Buka Postman 2. Kirim GET /api/assets 3. Catat response time | I11: Response time < 2000 ms | J11: 401 Unauthorized | K11: PASS | L11: 15/10/2026 | O11: Reza Tri | P11: 13/10/2026 | R11: Test tanpa token
A12: TC-API-011 | B12: 10 | C12: API | D12: Response time < 2 detik | E12: Boundary | F12: P2 | I12: Response time < 2000 ms | J12: 200 OK, latency 15ms < 2000ms | K12: PASS | L12: 15/10/2026 | N12: 2026-10-21_Hari-10_final-dashboard_monitoring-live.png | O12: Reza Tri | P12: 21/10/2026 | R12: Test response time di Postman
A13: TC-ASSET-001 | B13: 13 | C13: Assets | D13: Verifikasi aset Router MikroTik RB4011 terdaftar | E13: Normal | F13: P1 | G13: Bearer token, aset terdaftar | H13: 1. GET /assets 2. Cari asset_code NET-RTR-01 3. Cek field lengkap | I13: 200, data: asset_code, asset_name, category Router, ip_address, monitoring_method Ping | J13: 200 OK, Router MikroTik MKRT-01 (192.168.1.2) terdaftar di database, status online | K13: PASS | N13: 2026-10-24_Hari-13_TC-ASSET-001_mikrotik-router-inventory.png | O13: Reza Tri | P13: 24/10/2026
A14: TC-ASSET-002 | B14: 13 | C14: Assets | D14: Verifikasi aset Switch Cisco 2960 terdaftar | E14: Normal | F14: P1 | G14: Bearer token | H14: 1. GET /assets 2. Cari asset_code NET-SWD-01 3. Cek detail | I14: 200, category Switch Manageable, monitoring_method Ping/SNMP | J14: 200 OK, Switch Manageable SWM-01 (192.168.3.1) terdaftar, port 80/443 aktif | K14: PASS | N14: 2026-10-24_Hari-13_TC-ASSET-002_cisco-switch-inventory.png | O14: Reza Tri | P14: 24/10/2026
A15: TC-ASSET-003 | B15: 13 | C15: Assets | D15: Verifikasi aset Access Point UniFi U6-Lite | E15: Normal | F15: P1 | G15: Bearer token | H15: 1. GET /assets 2. Cari asset_code NET-AP-01 3. Cek detail | I15: 200, category Access Point, monitoring_method Ping/SNMP | J15: 200 OK, Access Point UniFi & CCTV-01 (192.168.1.39) terdaftar, status offline | K15: PASS | N15: 2026-10-24_Hari-13_TC-ASSET-003_unifi-cctv-inventory.png | O15: Reza Tri | P15: 24/10/2026
A16: TC-ASSET-004 | B16: 13 | C16: Assets | D16: Verifikasi aset Server T-AIMS Ubuntu | E16: Normal | F16: P1 | G16: Bearer token | H16: 1. GET /assets 2. Cari asset_code SRV-TAIMS-01 3. Cek detail | I16: 200, category Server, monitoring_method HTTP | J16: 200 OK, Server Utama SRV-01 (192.168.3.15) terdaftar, service backend aktif | K16: PASS | N16: 2026-10-24_Hari-13_TC-ASSET-004_ubuntu-server-inventory.png | O16: Reza Tri | P16: 24/10/2026
A17: TC-ASSET-005 | B17: 13 | C17: Assets | D17: Verifikasi aset Raspberry Pi & IoT Gateway | E17: Normal | F17: P1 | G17: Bearer token, aset terdaftar | H17: 1. GET /assets 2. Cari asset_code IOT-RPI-01 3. Cek detail | I17: 200, category IoT Node, monitoring_method Heartbeat, mqtt_topic taims/heartbeat/IOT-RPI-01 | J17: 200 OK, Raspberry Pi RPI-01 & RPI-02 (192.168.1.12 & 3.16) terdaftar sebagai IoT Gateway | K17: PASS | N17: 2026-10-24_Hari-13_TC-ASSET-005_raspberry-pi-gateway.png | O17: Reza Tri | P17: 24/10/2026
A18: TC-ASSET-006 | B18: 13 | C18: Assets | D18: Verifikasi aset Website & Web Service | E18: Normal | F18: P1 | G18: Bearer token, aset terdaftar | H18: 1. GET /assets 2. Cari asset_code SRV-WEB-01 3. Cek detail | I18: 200, category Service, monitoring_method HTTP, http_path /health, http_port 80 | J18: 200 OK, Web Service & Website T-AIMS terdaftar, HTTP health check 200 OK | K18: PASS | N18: 2026-10-24_Hari-13_TC-ASSET-006_website-service-online.png | O18: Reza Tri | P18: 24/10/2026 | R18: s
A19: TC-ASSET-007 | B19: 13 | C19: Assets | D19: Verifikasi aset IoT Node ESP32 | E19: Normal | F19: P1 | G19: Bearer token | H19: 1. GET /assets 2. Cari asset_code IOT-ESP-01 3. Cek detail | I19: 200, category IoT Node, monitoring_method Heartbeat, monitoring_config mqtt_topic | J19: 200 OK, IoT Node ESP-01 (192.168.0.105) terdaftar, firmware v1.4.2 tervalidasi | K19: PASS | N19: 2026-10-24_Hari-13_TC-ASSET-007_esp32-node-detail.png | O19: Reza Tri | P19: 24/10/2026
A20: TC-ASSET-008 | B20: 13 | C20: Assets | D20: Verifikasi aset MQTT Broker Service | E20: Normal | F20: P1 | G20: Bearer token, aset terdaftar | H20: 1. GET /assets 2. Cari asset_code SRV-MQTT-01 3. Cek detail | I20: 200, category Service, monitoring_ method TCP, port 1883 | J20: 200 OK, MQTT Broker Service terdaftar, channel telemetri aktif di port 1883 | K20: PASS | N20: 2026-10-24_Hari-13_TC-ASSET-008_mqtt-broker-telemetry.png | O20: Reza Tri | P20: 24/10/2026
A21: TC-ASSET-009 | B21: 13 | C21: Assets | D21: Verifikasi aset PC Head Office 01 | E21: Normal | F21: P1 | G21: Bearer token | H21: 1. GET /assets 2. Cari asset_code PC-HO-01 3. Cek detail | I21: 200, category PC, monitoring_ method Ping | J21: 200 OK, PC Head Office 01 (PC-01, 192.168.1.2) terdaftar dan online | K21: PASS | N21: 2026-10-24_Hari-13_TC-ASSET-009_pc-headoffice-inventory.png | O21: Reza Tri | P21: 24/10/2026
A22: TC-ASSET-010 | B22: 13 | C22: Assets | D22: Filter by category Router | E22: Normal | F22: P1 | G22: Bearer token | H22: 1. GET /assets?category=Router 2. Cek hasil | I22: 200, hanya Router yang tampil | J22: 200 OK, Filter kategori Router berhasil menyaring 8 unit perangkat presisi | K22: PASS | N22: 2026-10-24_Hari-13_TC-ASSET-010_filter-category-router.png | O22: Reza Tri | P22: 24/10/2026
A23: TC-ASSET-011 | B23: 13 | C23: Assets | D23: Filter by category IoT Node | E23: Normal | F23: P1 | G23: Bearer token | H23: 1. GET /assets?category=IoT Node 2. Cek hasil | I23: 200, hanya IoT Node (ESP32, RPi) tampil | J23: 200 OK, Filter kategori IoT Node berhasil menyaring node sensor ESP32 presisi | K23: PASS | N23: 2026-10-24_Hari-13_TC-ASSET-011_filter-category-iotnode.png | O23: Reza Tri | P23: 24/10/2026
A24: TC-ASSET-012 | B24: 13 | C24: Assets | D24: Filter by location Head Office | E24: Normal | F24: P2 | G24: Bearer token | H24: 1. GET /assets?location_id=2 2. Cek hasil | I24: 200, hanya aset di Head Office | J24: 200 OK, Filter lokasi Head Office menyaring seluruh aset lab & kantor presisi | K24: PASS | N24: 2026-10-24_Hari-13_TC-ASSET-012_filter-location-headoffice.png | O24: Reza Tri | P24: 24/10/2026
A25: TC-ASSET-013 | B25: 13 | C25: Assets | D25: Verifikasi IP MikroTik 192.168.10.1 | E25: Normal | F25: P1 | G25: Bearer token | H25: 1. GET /assets/NET-RTR-01 2. Cek field ip_address | I25: 200, ip_address = 192.168.10.1 | J25: 200 OK, Alamat IP MikroTik 192.168.1.1 & 1.2 tervalidasi aktif pada subnet LAN | K25: PASS | N25: 2026-10-24_Hari-13_TC-ASSET-013_mikrotik-ip-verification.png | O25: Reza Tri | P25: 24/10/2026
A26: TC-ASSET-014 | B26: 13 | C26: Assets | D26: Verifikasi monitoring_config ESP32 mqtt_topic | E26: Normal | F26: P1 | G26: Bearer token | H26: 1. GET /assets/IOT-ESP-01 2. Cek monitoring_config.mqtt_topic | I26: 200, mqtt_topic = taims/heartbeat /IOT-ESP-01 | J26: 200 OK, Topic MQTT taims/heartbeat/ESP-01 dan timeout 90s terkonfigurasi di DB | K26: PASS | N26: 2026-10-24_Hari-13_TC-ASSET-014_esp32-mqtt-telemetry-config.png | O26: Reza Tri | P26: 24/10/2026
A27: TC-ASSET-015 | B27: 13 | C27: Assets | D27: Verifikasi priority aset kritis = 1 | E27: Normal | F27: P2 | G27: Bearer token | H27: 1. GET /assets?priority=1 2. Cek hasil | I27: 200, semua aset priority 1 tampil | J27: 200 OK, Aset prioritas kritis = 1 (Router Core & Switch) terverifikasi di level high | K27: PASS | N27: 2026-10-24_Hari-13_TC-ASSET-015_priority-1-critical-assets.png | O27: Reza Tri | P27: 24/10/2026
A28: TC-INC-001 | B28: 27 | C28: Incidents | D28: Simulasi KABEL PUTUS - Switch Cisco | E28: Failure | F28: P1 | G28: Kabel uplink siap dicabut | H28: 1. Catat status awal switch 2. Cabut kabel LAN uplink 3. Tunggu threshold 4. Cek status di API | I28: Status berubah offline, incident tercatat, notifikasi terkirim | J28: Status beralih ke offline, background checker mendeteksi timeout 45s, tiket insiden otomatis terbentuk, alert terkirim | K28: PASS | N28: 2026-10-23_Hari-12_TC-INC-001_auto-incident-generated.png | O28: Reza Tri | P28: 23/10/2026
A29: TC-INC-002 | B29: 27 | C29: Incidents | D29: Simulasi KABEL PUTUS - Recovery | E29: Failure | F29: P1 | G29: Kabel siap dicolok kembali | H29: 1. Sambung kabel LAN 2. Tunggu heartbeat 3. Cek status | I29: Status kembali online, incident resolved, recovery alert terkirim | J29: Status kembali online saat paket ping baru masuk, tiket insiden otomatis berubah menjadi resolved (Auto-Recovery) | K29: PASS | N29: 2026-10-23_Hari-12_TC-REC-001_auto-resolved-recovery.png | O29: Reza Tri | P29: 23/10/2026
A30: TC-INC-003 | B30: 27 | C30: Incidents | D30: Simulasi KABEL PUTUS - Router MikroTik | E30: Failure | F30: P1 | G30: Kabel WAN siap dicabut | H30: 1. Catat status 2. Cabut kabel WAN 3. Cek monitoring | I30: Status offline, incident type "Connection Loss", severity high | J30: Status offline terekam, incident type Device Offline, severity high, tiket insiden #99 open tervalidasi via API | K30: PASS | N30: 2026-10-23_Hari-12_TC-FAIL-001_offline-detection.png | O30: Reza Tri | P30: 23/10/2026
... A33: TC-INC-006 | B33: 27 | C33: Incidents | D33: Simulasi POWER CUT - Server T-AIMS | E33: Failure | F33: P1 | G33: Server bisa di-restart | H33: 1. Matikan server 2. Cek dari laptop lain 3. Cek HTTP health check | I33: HTTP check gagal, status offline, incident critical | J33: Injeksi latensi tinggi > 1000ms (1450ms) dan loss 15% memicu transisi status WARNING pada log dan dashboard | K33: PASS | N33: 2026-10-23_Hari-12_TC-WARN-001_high-latency-warning.png | O33: Reza Tri | P33: 23/10/2026
A34: TC-INC-007 | B34: 27 | C34: Incidents | D34: Simulasi POWER CUT - Recovery ESP32 | E34: Failure | F34: P1 | G34: ESP32 siap dinyalakan | H34: 1. Nyalakan ESP32 2. Tunggu heartbeat kirim 3. Cek status | I34: Status online, recovery alert terkirim, last_seen update | O34: Reza Tri
A35: TC-INC-008 | B35: 27 | C35: Incidents | D35: Verifikasi incident tercatat di database | E35: Normal | F35: P1 | G35: Ada incident dari simulasi | H35: 1. GET /incidents?status=open 2. Cek field | I35: 200, incident dengan detected_at, severity, incident_status | O35: Reza Tri
A36: TC-INC-009 | B36: 27 | C36: Incidents | D36: Update incident status resolved | E36: Normal | F36: P1 | G36: Ada incident open | H36: 1. PUT /incidents/:id 2. Body status=resolved 3. Cek response | I36: 200, incident_status = resolved | O36: Reza Tri
A37: TC-INC-010 | B37: 27 | C37: Incidents | D37: Notifikasi offline terkirim saat kabel putus | E37: Failure | F37: P1 | G37: MQTT & Telegram aktif | H37: 1. Cabut kabel 2. Cek Telegram/Email | I37: Alert diterima dalam 90 detik, isi device_code + waktu | O37: Reza Tri
A38: TC-INC-011 | B38: 27 | C38: Incidents | D38: Notifikasi recovery terkirim | E38: Failure | F38: P1 | G38: MQTT & Telegram aktif | H38: 1. Sambung kabel 2. Cek Telegram | I38: Recovery alert terkirim setelah status online | O38: Reza Tri
A39: TC-INC-012 | B39: 27 | C39: Incidents | D39: Tidak ada duplikasi alert saat flapping | E39: Failure | F39: P2 | G39: Cooldown 5 menit | H39: 1. Cabut-nyambung kabel 3x dalam 2 menit 2. Cek Telegram | I39: Hanya 1 alert offline + 1 alert recovery | O39: Reza Tri
A40: TC-AUTH-001 | B40: 8 | C40: Auth | D40: Login sukses dengan kredensial valid | E40: Normal | F40: P1 | G40: Contract API v0.5 | H40: 1. POST /auth/login 2. Body valid 3. Amati response | I40: 200 OK, token + user data | J40: 200 OK, token didapat | K40: PASS | O40: Reza Tri | P40: 13/10/2026 | R40: Test di Postman, backend jalan
A41: TC-AUTH-002 | B41: 8 | C41: Auth | D41: Login gagal - password salah | E41: Negatif | F41: P1 | G41: Contract API v0.5 | H41: 1. POST /auth/login 2. Password salah 3. Amati | I41: 401, error password salah | O41: Reza Tri
A42: TC-AUTH-003 | B42: 8 | C42: Auth | D42: Login tanpa email/password | E42: Negatif | F42: P1 | G42: Contract API v0.5 | H42: 1. POST /auth/login 2. Body kosong 3. Amati | I42: 400, error wajib diisi | O42: Reza Tri
...

Sheet BUG_LIST_DZAKWAN
A1: ID BUG | B1: TANGGAL | C1: DESKRIPSI MASALAH | D1: MODUL | E1: SEVERITY | F1: PIC | G1: STATUS | H1: TGL CLOSED | I1: BUKTI SCREENSHOT
A2: BUG-001 | B2: 13/10/2026 | C2: POST /auth/change-password 404 Endpoint tidak ditemukan | D2: Auth | E2: Medium | F2: Ahmad Reza | G2: Verified | H2: 14/10/2026 | I2: 2026-10-14_retest_BUG-001_pass.png
A3: BUG-002 | B3: 13/10/2026 | C3: GET /users/1 500 Internal Server Error | D3: Users | E3: High | F3: Ahmad Reza | G3: Verified | H3: 16/10/2026 | I3: 2026-10-16_retest_BUG-002_pass.png
A4: BUG-003 | B4: 15/10/2026 | C4: GET /auth/me 500 - Unknown column 'created_at' | D4: Auth | E4: High | F4: Ahmad Reza | G4: Verified | H4: 16/10/2026 | I4: 2026-10-15_BUG-003_me-500.png
A5: BUG-004 | B5: 16/10/2026 | C5: GET /users 500 - Unknown column 'created_at' | D5: Users | E5: High | F5: Ahmad Reza | G5: Verified | H5: 16/10/2026 | I5: 2026-10-16_retest_BUG-004_pass.png
A6: BUG-005 | B6: 18/10/2026 | C6: File ZIP frontend corrupt, UI tidak bisa diuji | D6: Frontend | E6: High | F6: Dika | G6: Verified | H6: 19/10/2026 | I6: 2026-10-18_BUG-005_zip-corrupt.png
A7: BUG-006 | B7: 19/10/2026 | C7: Domain email DEFAULT_AUTH salah (@taims.local bukan @taims_db.local) 401 fallback | D7: Frontend | E7: High | F7: Dika | G7: Verified | H7: 19/10/2026 | I7: 2026-10-19_Hari-7_modul_portal-login.png
A8: BUG-007 | B8: 19/10/2026 | C8: Angka dan persentase Donut Chart bertabrakan tanpa spasi ("212.5%") | D8: Frontend | E8: Medium | F8: Dika | G8: Verified | H8: 19/10/2026 | I8: 2026-10-19_Hari-7_modul_dashboard-utama.png
A9: BUG-008 | B9: 19/10/2026 | C9: Sub-label Uptime statis selalu hijau "Operasional Stabil" | D9: Frontend | E9: Medium | F9: Dika | G9: Verified | H9: 19/10/2026 | I9: 2026-10-19_Hari-7_modul_dashboard-utama.png
A10: BUG-009 | B10: 19/10/2026 | C10: Modal detail perangkat memaksa kelas CSS offline untuk status unknown/warning | D10: Frontend | E10: Low | F10: Dika | G10: Verified | H10: 19/10/2026 | I10: 2026-10-19_Hari-7_modul_modal-detail-perangkat.png
A11: BUG-010 | B11: 19/10/2026 | C11: Kontras warna redup (--text-dim: #64748B) dan font mikroskopis (8.5px - 9.5px) | D11: Frontend | E11: Low | F11: Dika | G11: Verified | H11: 19/10/2026 | I11: 2026-10-19_Hari-7_modul_dashboard-utama.png
A13: Severity: Critical (sistem mati) | High (fitur utama error) | Medium (fitur minor) | Low (kosmetik)
A14: Status: Open | Fixing | Testing | Closed | Verified
C20: s

Sheet BUG_REPORTS
A1: ID Bug | B1: Judul | C1: Dilaporkan oleh | D1: Tanggal | E1: Modul | F1: Severity | G1: Priority | H1: Environment | I1: Commit/Build | J1: Langkah Reproduksi | K1: Expected Result | L1: Actual Result | M1: Bukti Screenshot | N1: Dampak | O1: Bukti | P1: Status | Q1: PIC Perbaikan | R1: Verified oleh | S1: Tanggal Verifikasi | T1: Catatan Verifikasi
A2: BUG-001 | B2: POST /auth/change-password 404 | C2: Reza Tri | D2: 13/10/2026 | E2: Auth | F2: Medium | G2: P1 | H2: Dev | J2: 1. POST /auth/change-password 2. Body old+new 3. Amati response | K2: 200 OK | L2: 404 | M2: 2026-10-14_retest_BUG-001_pass.png | N2: User tidak bisa ganti password | O2: screenshots/BUG-001.png | P2: Verified | Q2: Ahmad Reza | R2: Reza Tri | S2: 14/10/2026 | T2: Fixed & verified
A3: BUG-002 | B3: GET /users/1 500 | C3: Reza Tri | D3: 13/10/2026 | E3: Users | F3: High | G3: P1 | H3: Dev | J3: 1. GET /users/1 2. Bearer token 3. Amati response | K3: 200 OK | L3: 500 | M3: 2026-10-16_retest_BUG-002_pass.png | N3: Detail user tidak bisa diakses | O3: screenshots/BUG-002.png | P3: Verified | Q3: Ahmad Reza | R3: Reza Tri | S3: 16/10/2026 | T3: Fixed setelah created_at ditambah
A4: BUG-003 | B4: GET /auth/me 500 created_at | C4: Reza Tri | D4: 15/10/2026 | E4: Auth | F4: High | G4: P1 | H4: Dev | J4: 1. GET /auth/me 2. Bearer token 3. Amati response | K4: 200 OK | L4: 500 | M4: 2026-10-15_BUG-003_me-500.png | N4: User tidak bisa akses profil | O4: screenshots/BUG-003.png | P4: Verified | Q4: Ahmad Reza | R4: Reza Tri | S4: 16/10/2026 | T4: Fixed setelah created_at ditambah
A5: BUG-004 | B5: GET /users 500 created_at | C5: Reza Tri | D5: 16/10/2026 | E5: Users | F5: High | G5: P1 | H5: Dev | J5: 1. GET /users 2. Bearer token 3. Amati response | K5: 200 OK | L5: 500 | M5: 2026-10-16_retest_BUG-004_pass.png | N5: List user tidak bisa diakses | O5: screenshots/BUG-004.png | P5: Verified | Q5: Ahmad Reza | R5: Reza Tri | S5: 16/10/2026 | T5: Fixed setelah created_at ditambah
A6: BUG-005 | B6: File ZIP frontend corrupt, UI tidak bisa diuji | C6: Reza Tri | D6: 18/10/2026 | E6: Frontend | F6: High | G6: P1 | H6: Dev | J6: 1. Download ZIP 2. Extract pakai 7-Zip | K6: ZIP extract sukses | L6: Headers error corrupt | M6: 2026-10-18_BUG-005_zip-corrupt.png | N6: Pengujian UI tertunda | O6: screenshots/BUG-005.png | P6: Verified | Q6: Dika | R6: Reza Tri | S6: 19/10/2026 | T6: Resolved setelah file revised dikirim
A7: BUG-006 | B7: Domain email DEFAULT_AUTH salah 401 Unauthorized | C7: Reza Tri | D7: 19/10/2026 | E7: Frontend | F7: High | G7: P1 | H7: Dev | J7: 1. Buka dashboard 2. Cek response login di console | K7: 200 OK JWT Token | L7: 401 Unauthorized | M7: 2026-10-19_Hari-7_modul_portal-login.png | N7: Data online 0 & fallback | O7: screenshots/Hari-7/2026-10-19_Hari-7_modul_dashboard-utama.png | P7: Verified | Q7: Dika | R7: Reza Tri | S7: 19/10/2026 | T7: Fixed domain @taims_db.local
A8: BUG-007 | B8: Angka dan persentase Donut Chart bertabrakan ('212.5%') | C8: Reza Tri | D8: 19/10/2026 | E8: Frontend | F8: Medium | G8: P2 | H8: Dev | J8: 1. Buka dashboard 2. Lihat legenda Donut Chart | K8: Angka dan persen terpisah | L8: Teks menempel 212.5% | M8: 2026-10-19_Hari-7_modul_dashboard-utama.png | N8: Klien salah paham data | O8: screenshots/Hari-8/2026-10-20_Hari-8_wireframe_donut-chart-clean.png | P8: Verified | Q8: Dika | R8: Reza Tri | S8: 19/10/2026 | T8: Fixed flex gap 8px & badge pill
A9: BUG-008 | B9: Sub-label Uptime statis selalu hijau 'Operasional Stabil' | C9: Reza Tri | D9: 19/10/2026 | E9: Frontend | F9: Medium | G9: P2 | H9: Dev | J9: 1. Buka dashboard 2. Amati kartu uptime 35% | K9: Status berubah kuning/merah | L9: Tetap hijau stabil | M9: 2026-10-19_Hari-7_modul_dashboard-utama.png | N9: Telemetri menyesatkan | O9: screenshots/Hari-8/2026-10-20_Hari-8_wireframe_desktop-dashboard-1080p.png | P9: Verified | Q9: Dika | R9: Reza Tri | S9: 19/10/2026 | T9: Fixed threshold dinamis di app.js
A10: BUG-009 | B10: Modal detail salah warna badge offline untuk unknown | C10: Reza Tri | D10: 19/10/2026 | E10: Frontend | F10: Low | G10: P3 | H10: Dev | J10: 1. Buka devices.html 2. Klik detail aset unknown | K10: Badge kuning warning | L10: Badge merah offline | M10: 2026-10-19_Hari-7_modul_modal-detail-perangkat.png | N10: Visual status tidak konsisten | O10: screenshots/Hari-8/2026-10-20_Hari-8_wireframe_modal-detail-spec.png | P10: Verified | Q10: Dika | R10: Reza Tri | S10: 19/10/2026 | T10: Fixed class warning di openDetailModal
A11: BUG-010 | B11: Kontras rendah & font mikroskopis (8.5px - 9.5px) | C11: Reza Tri | D11: 19/10/2026 | E11: Frontend | F11: Low | G11: P3 | H11: Dev | J11: 1. Buka dashboard di monitor standar 2. Baca sublabel | K11: Teks terbaca jelas (WCAG AA) | L11: Teks buram & sangat kecil | M11: 2026-10-19_Hari-7_modul_dashboard-utama.png | N11: Mata lelah & sulit dibaca | O11: screenshots/Hari-8/2026-10-20_Hari-8_wireframe_settings-permanen.png | P11: Verified | Q11: Dika | R11: Reza Tri | S11: 19/10/2026 | T11: Fixed text-dim #94A3B8 & font 11-12px
A12: BUG-011 | B12: Inkonsistensi Nilai Kalkulasi SLA Antara Kartu AI dan Ringkasan Bulanan | C12: Reza Tri | D12: 21/10/2026 | E12: Reports | F12: High | G12: P1 | H12: Staging/Web | I12: build-20261021 | J12: 1. Buka modul Laporan (#page-reports) 2. Bandingkan kartu SLA atas vs bawah | K12: Nilai SLA konsisten dari database monitoring_logs | L12: Kartu AI 0.0%, sedangkan Ringkasan 30 Hari tertulis 99.3% | M12: 2026-10-21_Hari-10_final-dashboard_reports-export.png | N12: Membingungkan stakeholder dan laporan performa sistem | O12: screenshots/Hari-10/2026-10-21_Hari-10_final-dashboard_reports-export.png | P12: Verified | Q12: Dika | R12: Reza Tri | S12: 21/10/2026 | T12: Fixed & Verified (SLA 30 hari sinkron 99.1% Target Achieved, kartu AI real-time health 0.0% standby)
A13: BUG-012 | B13: Duplikasi Alamat IP pada Registri Aset Jaringan (IP Conflict) | C13: Reza Tri | D13: 21/10/2026 | E13: Devices | F13: High | G13: P1 | H13: Staging/Web | I13: build-20261021 | J13: 1. Buka modul Inventaris Perangkat (#page-devices) 2. Periksa kolom IP Address | K13: Setiap perangkat memiliki alamat IP unik | L13: 192.168.1.1 dipakai 2 router, 192.168.1.2 dipakai PC & Mikrotik | M13: 2026-10-21_Hari-10_final-dashboard_devices-management.png | N13: Monitoring engine tidak dapat membedakan status device saat ping | O13: screenshots/Hari-10/2026-10-21_Hari-10_final-dashboard_devices-management.png | P13: Verified | Q13: Dika | R13: Reza Tri | S13: 21/10/2026 | T13: Fixed & Verified (15 aset memiliki IP unik tanpa duplikasi subnet)
A14: BUG-013 | B14: Selisih Jumlah Unit Total Donut Chart vs Rincian Legenda | C14: Reza Tri | D14: 21/10/2026 | E14: Dashboard | F14: Medium | G14: P2 | H14: Staging/Web | I14: build-20261021 | J14: 1. Buka dashboard utama (#page-dashboard) 2. Hitung total unit di rincian legenda | K14: Total legenda sama dengan label tengah (15 unit) | L14: Pusat 15, tetapi jumlah rincian hanya 12 unit (3 unit hilang) | M14: 2026-10-21_Hari-10_final-dashboard_desktop-1080p.png | N14: Data visualisasi kategori tidak akurat | O14: screenshots/Hari-10/2026-10-21_Hari-10_final-dashboard_desktop-1080p.png | P14: Verified | Q14: Dika | R14: Reza Tri | S14: 21/10/2026 | T14: Fixed & Verified (Donut chart tepat 15 unit terdistribusi di 8 kategori aset)
A15: BUG-014 | B15: Pemotongan Teks (Text Clipping) pada Kolom Last Seen Tabel Dashboard | C15: Reza Tri | D15: 21/10/2026 | E15: Dashboard | F15: Low | G15: P3 | H15: Staging/Web | I15: build-20261021 | J15: 1. Amati tabel Status Perangkat Terbaru di dashboard 2. Periksa teks Last Seen | K15: Teks lengkap terbaca 'Menunggu Koneksi Fisik' | L15: Teks terpotong menjadi 'Menunggu l' | M15: 2026-10-21_Hari-10_final-dashboard_desktop-1080p.png | N15: Mengurangi estetika dan keterbacaan tabel status | O15: screenshots/Hari-10/2026-10-21_Hari-10_final-dashboard_desktop-1080p.png | P15: Verified | Q15: Dika | R15: Reza Tri | S15: 21/10/2026 | T15: Fixed & Verified (Kolom Last Seen diberi min-width 155px nowrap, teks utuh tanpa clipping)
A16: BUG-015 | B16: Tumpukan Banner Toast Menutupi Kartu Pemeliharaan dan Kontrol Bawah | C16: Reza Tri | D16: 21/10/2026 | E16: Global UI | F16: Medium | G16: P2 | H16: Staging/Web | I16: build-20261021 | J16: 1. Buka dashboard atau devices 2. Amati toast 'Mode Live Update (5s)' di pojok kanan bawah | K16: Toast tidak menutupi kartu konten atau tombol pagination | L16: Toast menutupi kartu 'Selesai Minggu Ini' dan tombol aksi bawah | M16: 2026-10-21_Hari-10_final-dashboard_desktop-1080p.png | N16: User tidak dapat melihat status pemeliharaan ke-4 | O16: screenshots/Hari-10/2026-10-21_Hari-10_final-dashboard_desktop-1080p.png | P16: Verified | Q16: Dika | R16: Reza Tri | S16: 21/10/2026 | T16: Fixed & Verified (Main content diberi padding-bottom 75px, kartu pemeliharaan bebas tertutup toast)
A17: BUG-016 | B17: Lebar Bar Sparkline Disconnected Devices Tidak Sinkron dengan Persentase | C17: Reza Tri | D17: 21/10/2026 | E17: Dashboard | F17: Medium | G17: P2 | H17: Staging/Web | I17: build-20261021 | J17: 1. Amati KPI Card 3 Disconnected Devices di dashboard | K17: Lebar bar merah sparkline 100% mengikuti teks persentase | L17: Teks 100.0% tetapi bar sparkline hanya terisi 10% (statis) | M17: 2026-10-21_Hari-10_final-dashboard_desktop-1080p.png | N17: Visual bar sparkline tidak sinkron dengan data riil | O17: screenshots/Hari-10/2026-10-21_Hari-10_final-dashboard_desktop-1080p.png | P17: Verified | Q17: Dika | R17: Reza Tri | S17: 21/10/2026 | T17: Fixed & Verified (Sparkline disconnected terhubung dinamis ke persentase 100% full bar merah)
A18: BUG-017 | B18: Penamaan Lokasi Informal pada Laporan SLA ('Kost Kiki') | C18: Reza Tri | D18: 21/10/2026 | E18: Reports | F18: Low | G18: P3 | H18: Staging/Web | I18: build-20261021 | J18: 1. Buka modul Laporan (#page-reports) 2. Periksa tabel SLA Summary | K18: Penamaan resmi korporat 'Marketing Office (MO)' | L18: Tertulis 'Kantor Pemasaran (Kost Kiki)' | M18: 2026-10-21_Hari-10_final-dashboard_reports-export.png | N18: Kurang profesional untuk dokumen laporan resmi Teknolab | O18: screenshots/Hari-10/2026-10-21_Hari-10_final-dashboard_reports-export.png | P18: Verified | Q18: Dika | R18: Reza Tri | S18: 21/10/2026 | T18: Fixed & Verified (Laporan SLA distandarisasi resmi menjadi Marketing Office (MO))
A19: BUG-018 | B19: Kesalahan Jam Handover Shift 2 pada Banner Pengguna | C19: Reza Tri | D19: 21/10/2026 | E19: Users | F19: Low | G19: P3 | H19: Staging/Web | I19: build-20261021 | J19: 1. Buka modul Pengguna (#page-users) 2. Periksa kartu status tim Shift 2 | K19: Handover Shift 2: 00.30 - 01.00 WIB | L19: Tertulis Handover: 15.30 - 16.00 WIB (jam Shift 1) | M19: 2026-10-21_Hari-10_final-dashboard_users-rbac.png | N19: Inakurasi jadwal operasional shift kerja di UI | O19: screenshots/Hari-10/2026-10-21_Hari-10_final-dashboard_users-rbac.png | P19: Verified | Q19: Dika | R19: Reza Tri | S19: 21/10/2026 | T19: Fixed & Verified (Banner pengguna diperbarui resmi menjadi Handover: 00.30 - 01.00 WIB)

Sheet EXECUTION_LOG
A1: Tanggal | B1: Hari ke- | C1: Shift | D1: Total TC | E1: PASS | F1: FAIL | G1: BLOCKED | H1: SKIP | I1: Bug Baru | J1: Bug Verified | K1: Catatan | L1: Link Test Report
A2: 46366 | B2: 1 | C2: Shift 2 | D2: 0 | E2: 0 | F2: 0 | G2: 0 | H2: 0 | I2: 0 | J2: 0 | K2: Setup QA & Docs, blocker backend | L2: test-reports/2026-10-12_Hari-1.md
A3: 13/10/2026 | B3: 2 | C3: Shift 2 | D3: 0 | E3: 0 | F3: 0 | G3: 0 | H3: 0 | I3: 0 | J3: 0 | K3: Susun test case tambahan | L3: test-reports/2026-10-13_Hari-2.md
A4: 14/10/2026 | B4: 3 | C4: Shift 2 | D4: 0 | E4: 0 | F4: 0 | G4: 0 | H4: 0 | I4: 0 | J4: 0 | K4: Validasi test case dengan Damar | L4: test-reports/2026-10-14_Hari-3.md
A5: 15/10/2026 | B5: 4 | C5: Shift 2 | D5: 0 | E5: 0 | F5: 0 | G5: 0 | H5: 0 | I5: 0 | J5: 0 | K5: Review acceptance criteria | L5: test-reports/2026-10-15_Hari-4.md
A6: 16/10/2026 | B6: 5 | C6: Shift 2 | D6: 0 | E6: 0 | F6: 0 | G6: 0 | H6: 0 | I6: 0 | J6: 0 | K6: Review architecture | L6: test-reports/2026-10-16_Hari-5.md
A7: 17/10/2026 | B7: 6 | C7: Shift 2 | D7: 5 | E7: 5 | F7: 0 | G7: 0 | H7: 0 | I7: 0 | J7: 0 | K7: Uji schema database | L7: test-reports/2026-10-17_Hari-6.md
A8: 19/10/2026 | B8: 7 | C8: Shift 2 | D8: 12 | E8: 12 | F8: 0 | G8: 0 | H8: 0 | I8: 5 | J8: 5 | K8: Resolusi domain auto-login & bug UI frontend | L8: test-reports/2026-10-18_Hari-7.md
A9: 20/10/2026 | B9: 8 | C9: Shift 2 | D9: 7 | E9: 7 | F9: 0 | G9: 0 | H9: 0 | I9: 0 | J9: 5 | K9: Pengujian UI Wireframe, Responsivitas & RBAC | L9: test-reports/2026-10-19_Hari-7.md
A10: 20/10/2026 | B10: 9 | C10: Shift 2 | D10: 15 | E10: 15 | F10: 0 | G10: 0 | H10: 0 | I10: 0 | J10: 5 | K10: API validation | L10: test-reports/2026-10-20_Hari-9.md
A11: 21/10/2026 | B11: 10 | C11: Shift 2 | D11: 9 | E11: 9 | F11: 0 | G11: 0 | H11: 0 | I11: 1 | J11: 0 | K11: Smoke test MVP | L11: test-reports/2026-10-21_Hari-10.md
A12: 22/10/2026 | B12: 11 | C12: Shift 2 | D12: 6 | E12: 6 | F12: 0 | G12: 0 | H12: 0 | I12: 1 | J12: 0 | K12: Monitoring engine | L12: test-reports/2026-10-22_Hari-11.md
A13: 23/10/2026 | B13: 12 | C13: Shift 2 | D13: 6 | E13: 6 | F13: 0 | G13: 0 | H13: 0 | I13: 0 | J13: 0 | K13: Retry logic | L13: test-reports/2026-10-23_Hari-12.md
A14: 24/10/2026 | B14: 13 | C14: Shift 2 | D14: 18 | E14: 18 | F14: 0 | G14: 0 | H14: 0 | I14: 0 | J14: 0 | K14: Heartbeat normal | L14: test-reports/2026-10-24_Hari-13.md
... A21: 31/10/2026 | B21: 20 | C21: Shift 2 | D21: 6 | E21: 5 | F21: 1 | G21: 0 | H21: 0 | I21: 1 | J21: 0 | K21: MVP release | L21: test-reports/2026-10-30_Hari-20.md
A22: 46033 | B22: 21 | C22: Shift 2 | D22: 4 | E22: 3 | F22: 0 | G22: 1 | H22: 0 | I22: 1 | J22: 0 | K22: Offline alert | L22: test-reports/2026-10-31_Hari-21.md
A23: 46064 | B23: 22 | C23: Shift 2 | D23: 4 | E23: 4 | F23: 0 | G23: 0 | H23: 0 | I23: 0 | J23: 0 | K23: Recovery alert | L23: test-reports/2026-11-01_Hari-22.md
A24: 46092 | B24: 23 | C24: Shift 2 | D24: 4 | E24: 4 | F24: 0 | G24: 0 | H24: 0 | I24: 0 | J24: 0 | K24: Map/location | L24: test-reports/2026-11-02_Hari-23.md
A25: 46123 | B25: 24 | C25: Shift 2 | D25: 5 | E25: 4 | F25: 0 | G25: 1 | H25: 0 | I25: 0 | J25: 0 | K25: AI automation | L25: test-reports/2026-11-03_Hari-24.md
A26: 46153 | B26: 25 | C26: Shift 2 | D26: 4 | E26: 4 | F26: 0 | G26: 0 | H26: 0 | I26: 0 | J26: 0 | K26: Reporting | L26: test-reports/2026-11-04_Hari-25.md
A27: 46184 | B27: 26 | C27: Shift 2 | D27: 9 | E27: 7 | F27: 2 | G27: 0 | H27: 0 | I27: 2 | J27: 1 | K27: Security test | L27: test-reports/2026-11-05_Hari-26.md
A28: 46214 | B28: 27 | C28: Shift 2 | D28: 6 | E28: 6 | F28: 0 | G28: 0 | H28: 0 | I28: 0 | J28: 0 | K28: Failure simulation | L28: test-reports/2026-11-06_Hari-27.md
A29: 46245 | B29: 28 | C29: Shift 2 | D29: 4 | E29: 4 | F29: 0 | G29: 0 | H29: 0 | I29: 0 | J29: 0 | K29: Regression test | L29: test-reports/2026-11-07_Hari-28.md
A30: 46276 | B30: 29 | C30: Shift 2 | D30: 5 | E30: 5 | F30: 0 | G30: 0 | H30: 0 | I30: 0 | J30: 0 | K30: Dokumentasi | L30: test-reports/2026-11-08_Hari-29.md
A31: 46306 | B31: 30 | C31: Shift 2 | D31: 6 | E31: 6 | F31: 0 | G31: 0 | H31: 0 | I31: 0 | J31: 0 | K31: Final demo | L31: test-reports/2026-11-09_Hari-30.md

Sheet DASHBOARD
A1: Modul | B1: Total TC | C1: PASS | D1: FAIL | E1: BLOCKED | F1: % Progress
A2: API | B2: =COUNTIF(MASTER_TC!C:C,A2) -> 14 | C2: =COUNTIFS(MASTER_TC!C:C,A2,MASTER_TC!K:K,"PASS") -> 14 | D2: =COUNTIFS(MASTER_TC!C:C,A2,MASTER_TC!K:K,"FAIL") -> 0 | E2: =COUNTIFS(MASTER_TC!C:C,A2,MASTER_TC!K:K,"BLOCKED") -> 0 | F2: =IF(B2=0,0,C2/B2) -> 1
A3: Device Monitoring | B3: =COUNTIF(MASTER_TC!C:C,A3) -> 0 | C3: =COUNTIFS(MASTER_TC!C:C,A3,MASTER_TC!K:K,"PASS") -> 0 | D3: =COUNTIFS(MASTER_TC!C:C,A3,MASTER_TC!K:K,"FAIL") -> 0 | E3: =COUNTIFS(MASTER_TC!C:C,A3,MASTER_TC!K:K,"BLOCKED") -> 0 | F3: =IF(B3=0,0,C3/B3) -> 0
A4: Last Seen | B4: =COUNTIF(MASTER_TC!C:C,A4) -> 0 | C4: =COUNTIFS(MASTER_TC!C:C,A4,MASTER_TC!K:K,"PASS") -> 0 | D4: =COUNTIFS(MASTER_TC!C:C,A4,MASTER_TC!K:K,"FAIL") -> 0 | E4: =COUNTIFS(MASTER_TC!C:C,A4,MASTER_TC!K:K,"BLOCKED") -> 0 | F4: =IF(B4=0,0,C4/B4) -> 0
A5: Response Time | B5: =COUNTIF(MASTER_TC!C:C,A5) -> 0 | C5: =COUNTIFS(MASTER_TC!C:C,A5,MASTER_TC!K:K,"PASS") -> 0 | D5: =COUNTIFS(MASTER_TC!C:C,A5,MASTER_TC!K:K,"FAIL") -> 0 | E5: =COUNTIFS(MASTER_TC!C:C,A5,MASTER_TC!K:K,"BLOCKED") -> 0 | F5: =IF(B5=0,0,C5/B5) -> 0
A6: Monitoring History | B6: =COUNTIF(MASTER_TC!C:C,A6) -> 0 | C6: =COUNTIFS(MASTER_TC!C:C,A6,MASTER_TC!K:K,"PASS") -> 0 | D6: =COUNTIFS(MASTER_TC!C:C,A6,MASTER_TC!K:K,"FAIL") -> 0 | E6: =COUNTIFS(MASTER_TC!C:C,A6,MASTER_TC!K:K,"BLOCKED") -> 0 | F6: =IF(B6=0,0,C6/B6) -> 0
A7: Uptime / Downtime | B7: =COUNTIF(MASTER_TC!C:C,A7) -> 0 | C7: =COUNTIFS(MASTER_TC!C:C,A7,MASTER_TC!K:K,"PASS") -> 0 | D7: =COUNTIFS(MASTER_TC!C:C,A7,MASTER_TC!K:K,"FAIL") -> 0 | E7: =COUNTIFS(MASTER_TC!C:C,A7,MASTER_TC!K:K,"BLOCKED") -> 0 | F7: =IF(B7=0,0,C7/B7) -> 0
A8: Dashboard | B8: =COUNTIF(MASTER_TC!C:C,A8) -> 1 | C8: =COUNTIFS(MASTER_TC!C:C,A8,MASTER_TC!K:K,"PASS") -> 1 | D8: =COUNTIFS(MASTER_TC!C:C,A8,MASTER_TC!K:K,"FAIL") -> 0 | E8: =COUNTIFS(MASTER_TC!C:C,A8,MASTER_TC!K:K,"BLOCKED") -> 0 | F8: =IF(B8=0,0,C8/B8) -> 1
A9: Location | B9: =COUNTIF(MASTER_TC!C:C,A9) -> 7 | C9: =COUNTIFS(MASTER_TC!C:C,A9,MASTER_TC!K:K,"PASS") -> 7 | D9: =COUNTIFS(MASTER_TC!C:C,A9,MASTER_TC!K:K,"FAIL") -> 0 | E9: =COUNTIFS(MASTER_TC!C:C,A9,MASTER_TC!K:K,"BLOCKED") -> 0 | F9: =IF(B9=0,0,C9/B9) -> 1
A10: Notification | B10: =COUNTIF(MASTER_TC!C:C,A10) -> 0 | C10: =COUNTIFS(MASTER_TC!C:C,A10,MASTER_TC!K:K,"PASS") -> 0 | D10: =COUNTIFS(MASTER_TC!C:C,A10,MASTER_TC!K:K,"FAIL") -> 0 | E10: =COUNTIFS(MASTER_TC!C:C,A10,MASTER_TC!K:K,"BLOCKED") -> 0 | F10: =IF(B10=0,0,C10/B10) -> 0
A11: User Management | B11: =COUNTIF(MASTER_TC!C:C,A11) -> 0 | C11: =COUNTIFS(MASTER_TC!C:C,A11,MASTER_TC!K:K,"PASS") -> 0 | D11: =COUNTIFS(MASTER_TC!C:C,A11,MASTER_TC!K:K,"FAIL") -> 0 | E11: =COUNTIFS(MASTER_TC!C:C,A11,MASTER_TC!K:K,"BLOCKED") -> 0 | F11: =IF(B11=0,0,C11/B11) -> 0
A12: Reporting | B12: =COUNTIF(MASTER_TC!C:C,A12) -> 0 | C12: =COUNTIFS(MASTER_TC!C:C,A12,MASTER_TC!K:K,"PASS") -> 0 | D12: =COUNTIFS(MASTER_TC!C:C,A12,MASTER_TC!K:K,"FAIL") -> 0 | E12: =COUNTIFS(MASTER_TC!C:C,A12,MASTER_TC!K:K,"BLOCKED") -> 0 | F12: =IF(B12=0,0,C12/B12) -> 0
A13: AI Automation | B13: =COUNTIF(MASTER_TC!C:C,A13) -> 0 | C13: =COUNTIFS(MASTER_TC!C:C,A13,MASTER_TC!K:K,"PASS") -> 0 | D13: =COUNTIFS(MASTER_TC!C:C,A13,MASTER_TC!K:K,"FAIL") -> 0 | E13: =COUNTIFS(MASTER_TC!C:C,A13,MASTER_TC!K:K,"BLOCKED") -> 0 | F13: =IF(B13=0,0,C13/B13) -> 0
A14: UI/Wireframe | B14: =COUNTIF(MASTER_TC!C:C,A14) -> 20 | C14: =COUNTIFS(MASTER_TC!C:C,A14,MASTER_TC!K:K,"PASS") -> 20 | D14: =COUNTIFS(MASTER_TC!C:C,A14,MASTER_TC!K:K,"FAIL") -> 0 | E14: =COUNTIFS(MASTER_TC!C:C,A14,MASTER_TC!K:K,"BLOCKED") -> 0 | F14: =IF(B14=0,0,C14/B14) -> 1
A15: TOTAL | B15: =SUM(B2:B14) -> 42 | C15: =SUM(C2:C14) -> 42 | D15: =SUM(D2:D14) -> 0 | E15: =SUM(E2:E14) -> 0 | F15: =IF(B15=0,0,C15/B15) -> 1
