Workbook

Sheet MASTER_TC
A1: TC ID | B1: Hari | C1: Modul | D1: Fitur | E1: Jenis Uji | F1: Prioritas | G1: Prasyarat | H1: Langkah Uji | I1: Expected Result | J1: Actual Result | K1: Status | L1: Severity | M1: Bug ID | N1: Bukti | O1: Penguji | P1: Tanggal Uji | Q1: Commit/Build | R1: Catatan
A2: TC-API-001 | C2: API | D2: GET List Assets | E2: Normal | F2: P1 | G2: Backend jalan, Postman siap | H2: 1. Buka Postman 2. Kirim GET /api/assets 3. Amati response | I2: HTTP 200, list aset tampil | O2: Reza Tri | R2: Test pertama — BLOCKED karena backend belum jalan
A3: TC-API-002 | B3: 8 | C3: API | D3: GET Detail Asset | E3: Normal | F3: P1 | I3: HTTP 200, detail aset tampil | O3: Reza Tri
A4: TC-API-003 | B4: 8 | C4: API | D4: POST Create Asset | E4: Normal | F4: P1 | I4: HTTP 201, aset tersimpan | O4: Reza Tri
A5: TC-API-004 | B5: 8 | C5: API | D5: POST tanpa field wajib | E5: Negatif | F5: P1 | I5: HTTP 400, error jelas | O5: Reza Tri
A6: TC-API-005 | B6: 8 | C6: API | D6: GET ID tidak ada | E6: Negatif | F6: P1 | I6: HTTP 404, error jelas | O6: Reza Tri
A7: TC-API-006 | B7: 9 | C7: API | D7: PUT Update Asset | E7: Normal | F7: P1 | I7: HTTP 200, data terupdate | O7: Reza Tri
A8: TC-API-007 | B8: 9 | C8: API | D8: DELETE Asset | E8: Normal | F8: P1 | I8: HTTP 200, aset terhapus | O8: Reza Tri
A9: TC-API-008 | B9: 9 | C9: API | D9: Validasi IP Address | E9: Boundary | F9: P2 | I9: HTTP 400, error jelas | O9: Reza Tri
A10: TC-API-009 | B10: 9 | C10: API | D10: Duplikasi Asset Code | E10: Negatif | F10: P1 | I10: HTTP 409, error duplicate | O10: Reza Tri
A11: TC-API-010 | B11: 9 | C11: API | D11: Endpoint tanpa auth | E11: Negatif | F11: P1 | I11: HTTP 401 Unauthorized | O11: Reza Tri
A12: TC-API-011 | B12: 10 | C12: API | D12: Response time < 2 detik | E12: Boundary | F12: P2 | I12: Response time < 2000 ms | O12: Reza Tri
A13: TC-ASSET-001 | B13: 13 | C13: Assets | D13: Verifikasi aset Router MikroTik RB4011 terdaftar | E13: Normal | F13: P1 | G13: Bearer token, aset terdaftar | H13: 1. GET /assets 2. Cari asset_code NET-RTR-01 3. Cek field lengkap | I13: 200, data: asset_code, asset_name, category Router, ip_address, monitoring_method Ping | K13: PASS | O13: Reza Tri | P13: 46366
A14: TC-ASSET-002 | B14: 13 | C14: Assets | D14: Verifikasi aset Switch Cisco 2960 terdaftar | E14: Normal | F14: P1 | G14: Bearer token | H14: 1. GET /assets 2. Cari asset_code NET-SWD-01 3. Cek detail | I14: 200, category Switch Manageable, monitoring_method Ping/SNMP | K14: PASS | O14: Reza Tri | P14: 46366
A15: TC-ASSET-003 | B15: 13 | C15: Assets | D15: Verifikasi aset Access Point UniFi U6-Lite | E15: Normal | F15: P1 | G15: Bearer token | H15: 1. GET /assets 2. Cari asset_code NET-AP-01 3. Cek detail | I15: 200, category Access Point, monitoring_method Ping/SNMP | K15: PASS | O15: Reza Tri | P15: 46366
A16: TC-ASSET-004 | B16: 13 | C16: Assets | D16: Verifikasi aset Server T-AIMS Ubuntu | E16: Normal | F16: P1 | G16: Bearer token | H16: 1. GET /assets 2. Cari asset_code SRV-TAIMS-01 3. Cek detail | I16: 200, category Server, monitoring_method HTTP | K16: PASS | O16: Reza Tri | P16: 46366
A17: TC-ASSET-005 | B17: 13 | C17: Assets | D17: Verifikasi aset Firewall pfSense | E17: Normal | F17: P1 | G17: Bearer token | H17: 1. GET /assets 2. Cari asset_code NET-FW-01 3. Cek detail | I17: 200, category Firewall, monitoring_method Ping | K17: PASS | O17: Reza Tri | P17: 46366
A18: TC-ASSET-006 | B18: 13 | C18: Assets | D18: Verifikasi aset Storage Synology DS220+ | E18: Normal | F18: P1 | G18: Bearer token | H18: 1. GET /assets 2. Cari asset_code STO-NAS-01 3. Cek detail | I18: 200, category Storage, monitoring_method Ping | K18: PASS | O18: Reza Tri | P18: 46366
A19: TC-ASSET-007 | B19: 13 | C19: Assets | D19: Verifikasi aset IoT Node ESP32 | E19: Normal | F19: P1 | G19: Bearer token | H19: 1. GET /assets 2. Cari asset_code IOT-ESP-01 3. Cek detail | I19: 200, category IoT Node, monitoring_method Heartbeat, monitoring_config mqtt_topic | K19: PASS | O19: Reza Tri | P19: 46366
A20: TC-ASSET-008 | B20: 13 | C20: Assets | D20: Verifikasi aset CCTV Head Office | E20: Normal | F20: P1 | G20: Bearer token | H20: 1. GET /assets 2. Cari asset_code SEC-CCTV-01 3. Cek detail | I20: 200, category CCTV, monitoring_method Ping + HTTP | K20: PASS | O20: Reza Tri | P20: 46366
A21: TC-ASSET-009 | B21: 13 | C21: Assets | D21: Verifikasi aset PC Head Office 01 | E21: Normal | F21: P1 | G21: Bearer token | H21: 1. GET /assets 2. Cari asset_code PC-HO-01 3. Cek detail | I21: 200, category PC, monitoring_method Ping | K21: PASS | O21: Reza Tri | P21: 46366
A22: TC-ASSET-010 | B22: 13 | C22: Assets | D22: Filter by category Router | E22: Normal | F22: P1 | G22: Bearer token | H22: 1. GET /assets?category=Router 2. Cek hasil | I22: 200, hanya Router yang tampil | K22: PASS | O22: Reza Tri | P22: 46366
A23: TC-ASSET-011 | B23: 13 | C23: Assets | D23: Filter by category IoT Node | E23: Normal | F23: P1 | G23: Bearer token | H23: 1. GET /assets?category=IoT Node 2. Cek hasil | I23: 200, hanya IoT Node (ESP32, RPi) tampil | K23: PASS | O23: Reza Tri | P23: 46366
A24: TC-ASSET-012 | B24: 13 | C24: Assets | D24: Filter by location Head Office | E24: Normal | F24: P2 | G24: Bearer token | H24: 1. GET /assets?location_id=2 2. Cek hasil | I24: 200, hanya aset di Head Office | K24: PASS | O24: Reza Tri | P24: 46366
... A27: TC-ASSET-015 | B27: 13 | C27: Assets | D27: Verifikasi priority aset kritis = 1 | E27: Normal | F27: P2 | G27: Bearer token | H27: 1. GET /assets?priority=1 2. Cek hasil | I27: 200, semua aset priority 1 tampil | K27: PASS | O27: Reza Tri | P27: 46366
A28: TC-INC-001 | B28: 27 | C28: Incidents | D28: Simulasi KABEL PUTUS - Switch Cisco | E28: Failure | F28: P1 | G28: Kabel uplink siap dicabut | H28: 1. Catat status awal switch 2. Cabut kabel LAN uplink 3. Tunggu threshold 4. Cek status di API | I28: Status berubah offline, incident tercatat, notifikasi terkirim | K28: PASS | O28: Reza Tri | P28: 27/10/2026
A29: TC-INC-002 | B29: 27 | C29: Incidents | D29: Simulasi KABEL PUTUS - Recovery | E29: Failure | F29: P1 | G29: Kabel siap dicolok kembali | H29: 1. Sambung kabel LAN 2. Tunggu heartbeat 3. Cek status | I29: Status kembali online, incident resolved, recovery alert terkirim | K29: PASS | O29: Reza Tri | P29: 27/10/2026
A30: TC-INC-003 | B30: 27 | C30: Incidents | D30: Simulasi KABEL PUTUS - Router MikroTik | E30: Failure | F30: P1 | G30: Kabel WAN siap dicabut | H30: 1. Catat status 2. Cabut kabel WAN 3. Cek monitoring | I30: Status offline, incident type "Connection Loss", severity high | K30: PASS | O30: Reza Tri | P30: 27/10/2026
A31: TC-INC-004 | B31: 27 | C31: Incidents | D31: Simulasi POWER CUT - Raspberry Pi | E31: Failure | F31: P1 | G31: RPi terpasang adaptor | H31: 1. Cabut adaptor power RPi 2. Tunggu 90 detik 3. Cek API status | I31: Status offline, last_seen stop, heartbeat berhenti | K31: PASS | O31: Reza Tri | P31: 27/10/2026
A32: TC-INC-005 | B32: 27 | C32: Incidents | D32: Simulasi POWER CUT - ESP32 | E32: Failure | F32: P1 | G32: ESP32 terpasang USB | H32: 1. Cabut USB power ESP32 2. Tunggu 90 detik 3. Cek API | I32: Status offline, LWT MQTT trigger offline | K32: PASS | O32: Reza Tri | P32: 27/10/2026
A33: TC-INC-006 | B33: 27 | C33: Incidents | D33: Simulasi POWER CUT - Server T-AIMS | E33: Failure | F33: P1 | G33: Server bisa di-restart | H33: 1. Matikan server 2. Cek dari laptop lain 3. Cek HTTP health check | I33: HTTP check gagal, status offline, incident critical | K33: PASS | O33: Reza Tri | P33: 27/10/2026
A34: TC-INC-007 | B34: 27 | C34: Incidents | D34: Simulasi POWER CUT - Recovery ESP32 | E34: Failure | F34: P1 | G34: ESP32 siap dinyalakan | H34: 1. Nyalakan ESP32 2. Tunggu heartbeat kirim 3. Cek status | I34: Status online, recovery alert terkirim, last_seen update | K34: PASS | O34: Reza Tri | P34: 27/10/2026
A35: TC-INC-008 | B35: 27 | C35: Incidents | D35: Verifikasi incident tercatat di database | E35: Normal | F35: P1 | G35: Ada incident dari simulasi | H35: 1. GET /incidents?status=open 2. Cek field | I35: 200, incident dengan detected_at, severity, incident_status | K35: PASS | O35: Reza Tri | P35: 27/10/2026
A36: TC-INC-009 | B36: 27 | C36: Incidents | D36: Update incident status resolved | E36: Normal | F36: P1 | G36: Ada incident open | H36: 1. PUT /incidents/:id 2. Body status=resolved 3. Cek response | I36: 200, incident_status = resolved | K36: PASS | O36: Reza Tri | P36: 27/10/2026
A37: TC-INC-010 | B37: 27 | C37: Incidents | D37: Notifikasi offline terkirim saat kabel putus | E37: Failure | F37: P1 | G37: MQTT & Telegram aktif | H37: 1. Cabut kabel 2. Cek Telegram/Email | I37: Alert diterima dalam 90 detik, isi device_code + waktu | K37: PASS | O37: Reza Tri | P37: 27/10/2026
A38: TC-INC-011 | B38: 27 | C38: Incidents | D38: Notifikasi recovery terkirim | E38: Failure | F38: P1 | G38: MQTT & Telegram aktif | H38: 1. Sambung kabel 2. Cek Telegram | I38: Recovery alert terkirim setelah status online | K38: PASS | O38: Reza Tri | P38: 27/10/2026
A39: TC-INC-012 | B39: 27 | C39: Incidents | D39: Tidak ada duplikasi alert saat flapping | E39: Failure | F39: P2 | G39: Cooldown 5 menit | H39: 1. Cabut-nyambung kabel 3x dalam 2 menit 2. Cek Telegram | I39: Hanya 1 alert offline + 1 alert recovery | K39: PASS | O39: Reza Tri | P39: 27/10/2026
A40: TC-AUTH-001 | B40: 8 | C40: Auth | D40: Login sukses dengan kredensial valid | E40: Normal | F40: P1 | G40: Contract API v0.5 | H40: 1. POST /auth/login 2. Body valid 3. Amati response | I40: 200 OK, token + user data | K40: PASS | O40: Reza Tri | P40: 46366
A41: TC-AUTH-002 | B41: 8 | C41: Auth | D41: Login gagal - password salah | E41: Negatif | F41: P1 | G41: Contract API v0.5 | H41: 1. POST /auth/login 2. Password salah 3. Amati | I41: 401, error password salah | K41: PASS | O41: Reza Tri | P41: 46366
A42: TC-AUTH-003 | B42: 8 | C42: Auth | D42: Login tanpa email/password | E42: Negatif | F42: P1 | G42: Contract API v0.5 | H42: 1. POST /auth/login 2. Body kosong 3. Amati | I42: 400, error wajib diisi | K42: PASS | O42: Reza Tri | P42: 46366
...

Sheet BUG_REPORTS
A1: Bug ID | B1: Judul | C1: Dilaporkan oleh | D1: Tanggal | E1: Modul | F1: Severity | G1: Priority | H1: Environment | I1: Commit/Build | J1: Langkah Reproduksi | K1: Expected Result | L1: Actual Result | M1: Frekuensi | N1: Dampak | O1: Bukti | P1: Status | Q1: PIC Perbaikan | R1: Verified oleh | S1: Tanggal Verifikasi | T1: Catatan Verifikasi
A2: BUG-001 | B2: Status device tetap Online padahal ESP32 mati | C2: Reza Tri | D2: 46336 | E2: Monitoring | F2: Critical | G2: P1 | H2: Staging | I2: abc1234 | J2: 1. ESP32 online 2. Matikan 3. Tunggu 6 menit 4. Refresh dashboard | K2: Status Offline | L2: Status masih Online | M2: Selalu | N2: Monitoring tidak akurat | O2: screenshots/BUG-001.png | P2: Open | Q2: Ananda | U2: Menunggu perbaikan
A3: BUG-002 | B3: Endpoint PUT 500 Internal Server Error | C3: Reza Tri | D3: 46336 | E3: API | F3: High | G3: P1 | H3: Staging | I3: abc1234 | J3: 1. PUT /api/assets/AST-001 2. Body valid 3. Amati response | K3: HTTP 200, data terupdate | L3: HTTP 500 | M3: Selalu | N3: Update aset tidak bisa | O3: screenshots/BUG-002.png | P3: Open | Q3: Ahmad Reza | U3: Menunggu fix

Sheet EXECUTION_LOG
A1: Tanggal | B1: Hari ke- | C1: Shift | D1: Total TC | E1: PASS | F1: FAIL | G1: BLOCKED | H1: SKIP | I1: Bug Baru | J1: Bug Verified | K1: Catatan | L1: Link Test Report
A2: 46336 | B2: 1 | C2: Shift 2 | D2: 0 | E2: 0 | F2: 0 | G2: 0 | H2: 0 | I2: 0 | J2: 0 | K2: Setup QA & Docs, blocker backend | L2: test-reports/2026-10-11_Hari-1.md
A3: 46366 | B3: 2 | C3: Shift 2 | D3: 0 | E3: 0 | F3: 0 | G3: 0 | H3: 0 | I3: 0 | J3: 0 | K3: Susun test case tambahan | L3: test-reports/2026-10-12_Hari-2.md
A4: 13/10/2026 | B4: 3 | C4: Shift 2 | D4: 0 | E4: 0 | F4: 0 | G4: 0 | H4: 0 | I4: 0 | J4: 0 | K4: Validasi test case dengan Damar | L4: test-reports/2026-10-13_Hari-3.md
A5: 14/10/2026 | B5: 4 | C5: Shift 2 | D5: 0 | E5: 0 | F5: 0 | G5: 0 | H5: 0 | I5: 0 | J5: 0 | K5: Review acceptance criteria | L5: test-reports/2026-10-14_Hari-4.md
A6: 15/10/2026 | B6: 5 | C6: Shift 2 | D6: 0 | E6: 0 | F6: 0 | G6: 0 | H6: 0 | I6: 0 | J6: 0 | K6: Review architecture | L6: test-reports/2026-10-15_Hari-5.md
A7: 16/10/2026 | B7: 6 | C7: Shift 2 | D7: 5 | E7: 5 | F7: 0 | G7: 0 | H7: 0 | I7: 0 | J7: 0 | K7: Uji schema database | L7: test-reports/2026-10-16_Hari-6.md
A8: 17/10/2026 | B8: 7 | C8: Shift 2 | D8: 3 | E8: 3 | F8: 0 | G8: 0 | H8: 0 | I8: 0 | J8: 0 | K8: Test checklist wireframe | L8: test-reports/2026-10-17_Hari-7.md
A9: 18/10/2026 | B9: 8 | C9: Shift 2 | D9: 5 | E9: 4 | F9: 1 | G9: 0 | H9: 0 | I9: 1 | J9: 0 | K9: API dasar + smoke test | L9: test-reports/2026-10-18_Hari-8.md
A10: 19/10/2026 | B10: 9 | C10: Shift 2 | D10: 5 | E10: 4 | F10: 1 | G10: 0 | H10: 0 | I10: 1 | J10: 1 | K10: API validation | L10: test-reports/2026-10-19_Hari-9.md
A11: 20/10/2026 | B11: 10 | C11: Shift 2 | D11: 4 | E11: 3 | F11: 1 | G11: 0 | H11: 0 | I11: 1 | J11: 0 | K11: Smoke test MVP | L11: test-reports/2026-10-20_Hari-10.md
A12: 21/10/2026 | B12: 11 | C12: Shift 2 | D12: 6 | E12: 5 | F12: 1 | G12: 0 | H12: 0 | I12: 1 | J12: 0 | K12: Monitoring engine | L12: test-reports/2026-10-21_Hari-11.md
A13: 22/10/2026 | B13: 12 | C13: Shift 2 | D13: 4 | E13: 4 | F13: 0 | G13: 0 | H13: 0 | I13: 0 | J13: 0 | K13: Retry logic | L13: test-reports/2026-10-22_Hari-12.md
A14: 23/10/2026 | B14: 13 | C14: Shift 2 | D14: 5 | E14: 5 | F14: 0 | G14: 0 | H14: 0 | I14: 0 | J14: 0 | K14: Heartbeat normal | L14: test-reports/2026-10-23_Hari-13.md
A15: 24/10/2026 | B15: 14 | C15: Shift 2 | D15: 5 | E15: 4 | F15: 1 | G15: 0 | H15: 0 | I15: 1 | J15: 0 | K15: Reconnect test | L15: test-reports/2026-10-24_Hari-14.md
... A22: 31/10/2026 | B22: 21 | C22: Shift 2 | D22: 4 | E22: 3 | F22: 0 | G22: 1 | H22: 0 | I22: 1 | J22: 0 | K22: Offline alert | L22: test-reports/2026-10-31_Hari-21.md
A23: 46033 | B23: 22 | C23: Shift 2 | D23: 4 | E23: 4 | F23: 0 | G23: 0 | H23: 0 | I23: 0 | J23: 0 | K23: Recovery alert | L23: test-reports/2026-11-01_Hari-22.md
A24: 46064 | B24: 23 | C24: Shift 2 | D24: 4 | E24: 4 | F24: 0 | G24: 0 | H24: 0 | I24: 0 | J24: 0 | K24: Map/location | L24: test-reports/2026-11-02_Hari-23.md
A25: 46092 | B25: 24 | C25: Shift 2 | D25: 5 | E25: 4 | F25: 0 | G25: 1 | H25: 0 | I25: 0 | J25: 0 | K25: AI automation | L25: test-reports/2026-11-03_Hari-24.md
A26: 46123 | B26: 25 | C26: Shift 2 | D26: 4 | E26: 4 | F26: 0 | G26: 0 | H26: 0 | I26: 0 | J26: 0 | K26: Reporting | L26: test-reports/2026-11-04_Hari-25.md
A27: 46153 | B27: 26 | C27: Shift 2 | D27: 9 | E27: 7 | F27: 2 | G27: 0 | H27: 0 | I27: 2 | J27: 1 | K27: Security test | L27: test-reports/2026-11-05_Hari-26.md
A28: 46184 | B28: 27 | C28: Shift 2 | D28: 6 | E28: 6 | F28: 0 | G28: 0 | H28: 0 | I28: 0 | J28: 0 | K28: Failure simulation | L28: test-reports/2026-11-06_Hari-27.md
A29: 46214 | B29: 28 | C29: Shift 2 | D29: 4 | E29: 4 | F29: 0 | G29: 0 | H29: 0 | I29: 0 | J29: 0 | K29: Regression test | L29: test-reports/2026-11-07_Hari-28.md
A30: 46245 | B30: 29 | C30: Shift 2 | D30: 5 | E30: 5 | F30: 0 | G30: 0 | H30: 0 | I30: 0 | J30: 0 | K30: Dokumentasi | L30: test-reports/2026-11-08_Hari-29.md
A31: 46276 | B31: 30 | C31: Shift 2 | D31: 6 | E31: 6 | F31: 0 | G31: 0 | H31: 0 | I31: 0 | J31: 0 | K31: Final demo | L31: test-reports/2026-11-09_Hari-30.md

Sheet DASHBOARD
A1: Modul | B1: Total TC | C1: PASS | D1: FAIL | E1: BLOCKED | F1: % Progress
A2: API | B2: =COUNTIF(MASTER_TC!C:C,A2) -> 11 | C2: =COUNTIFS(MASTER_TC!C:C,A2,MASTER_TC!K:K,"PASS") -> 0 | D2: =COUNTIFS(MASTER_TC!C:C,A2,MASTER_TC!K:K,"FAIL") -> 0 | E2: =COUNTIFS(MASTER_TC!C:C,A2,MASTER_TC!K:K,"BLOCKED") -> 0 | F2: =IFERROR(C2/B2,0) -> 0
A3: Device Monitoring | B3: =COUNTIF(MASTER_TC!C:C,A3) -> 0 | C3: =COUNTIFS(MASTER_TC!C:C,A3,MASTER_TC!K:K,"PASS") -> 0 | D3: =COUNTIFS(MASTER_TC!C:C,A3,MASTER_TC!K:K,"FAIL") -> 0 | E3: =COUNTIFS(MASTER_TC!C:C,A3,MASTER_TC!K:K,"BLOCKED") -> 0 | F3: =IF(B3=0,0,C3/B3) -> 0
A4: Last Seen | B4: =COUNTIF(MASTER_TC!C:C,A4) -> 0 | C4: =COUNTIFS(MASTER_TC!C:C,A4,MASTER_TC!K:K,"PASS") -> 0 | D4: =COUNTIFS(MASTER_TC!C:C,A4,MASTER_TC!K:K,"FAIL") -> 0 | E4: =COUNTIFS(MASTER_TC!C:C,A4,MASTER_TC!K:K,"BLOCKED") -> 0 | F4: =IF(B4=0,0,C4/B4) -> 0
A5: Response Time | B5: =COUNTIF(MASTER_TC!C:C,A5) -> 0 | C5: =COUNTIFS(MASTER_TC!C:C,A5,MASTER_TC!K:K,"PASS") -> 0 | D5: =COUNTIFS(MASTER_TC!C:C,A5,MASTER_TC!K:K,"FAIL") -> 0 | E5: =COUNTIFS(MASTER_TC!C:C,A5,MASTER_TC!K:K,"BLOCKED") -> 0 | F5: =IF(B5=0,0,C5/B5) -> 0
A6: Monitoring History | B6: =COUNTIF(MASTER_TC!C:C,A6) -> 0 | C6: =COUNTIFS(MASTER_TC!C:C,A6,MASTER_TC!K:K,"PASS") -> 0 | D6: =COUNTIFS(MASTER_TC!C:C,A6,MASTER_TC!K:K,"FAIL") -> 0 | E6: =COUNTIFS(MASTER_TC!C:C,A6,MASTER_TC!K:K,"BLOCKED") -> 0 | F6: =IF(B6=0,0,C6/B6) -> 0
A7: Uptime / Downtime | B7: =COUNTIF(MASTER_TC!C:C,A7) -> 0 | C7: =COUNTIFS(MASTER_TC!C:C,A7,MASTER_TC!K:K,"PASS") -> 0 | D7: =COUNTIFS(MASTER_TC!C:C,A7,MASTER_TC!K:K,"FAIL") -> 0 | E7: =COUNTIFS(MASTER_TC!C:C,A7,MASTER_TC!K:K,"BLOCKED") -> 0 | F7: =IF(B7=0,0,C7/B7) -> 0
A8: Dashboard | B8: =COUNTIF(MASTER_TC!C:C,A8) -> 5 | C8: =COUNTIFS(MASTER_TC!C:C,A8,MASTER_TC!K:K,"PASS") -> 5 | D8: =COUNTIFS(MASTER_TC!C:C,A8,MASTER_TC!K:K,"FAIL") -> 0 | E8: =COUNTIFS(MASTER_TC!C:C,A8,MASTER_TC!K:K,"BLOCKED") -> 0 | F8: =IF(B8=0,0,C8/B8) -> 1
A9: Location | B9: =COUNTIF(MASTER_TC!C:C,A9) -> 0 | C9: =COUNTIFS(MASTER_TC!C:C,A9,MASTER_TC!K:K,"PASS") -> 0 | D9: =COUNTIFS(MASTER_TC!C:C,A9,MASTER_TC!K:K,"FAIL") -> 0 | E9: =COUNTIFS(MASTER_TC!C:C,A9,MASTER_TC!K:K,"BLOCKED") -> 0 | F9: =IF(B9=0,0,C9/B9) -> 0
A10: Notification | B10: =COUNTIF(MASTER_TC!C:C,A10) -> 0 | C10: =COUNTIFS(MASTER_TC!C:C,A10,MASTER_TC!K:K,"PASS") -> 0 | D10: =COUNTIFS(MASTER_TC!C:C,A10,MASTER_TC!K:K,"FAIL") -> 0 | E10: =COUNTIFS(MASTER_TC!C:C,A10,MASTER_TC!K:K,"BLOCKED") -> 0 | F10: =IF(B10=0,0,C10/B10) -> 0
A11: User Management | B11: =COUNTIF(MASTER_TC!C:C,A11) -> 0 | C11: =COUNTIFS(MASTER_TC!C:C,A11,MASTER_TC!K:K,"PASS") -> 0 | D11: =COUNTIFS(MASTER_TC!C:C,A11,MASTER_TC!K:K,"FAIL") -> 0 | E11: =COUNTIFS(MASTER_TC!C:C,A11,MASTER_TC!K:K,"BLOCKED") -> 0 | F11: =IF(B11=0,0,C11/B11) -> 0
A12: Reporting | B12: =COUNTIF(MASTER_TC!C:C,A12) -> 0 | C12: =COUNTIFS(MASTER_TC!C:C,A12,MASTER_TC!K:K,"PASS") -> 0 | D12: =COUNTIFS(MASTER_TC!C:C,A12,MASTER_TC!K:K,"FAIL") -> 0 | E12: =COUNTIFS(MASTER_TC!C:C,A12,MASTER_TC!K:K,"BLOCKED") -> 0 | F12: =IF(B12=0,0,C12/B12) -> 0
A13: AI Automation | B13: =COUNTIF(MASTER_TC!C:C,A13) -> 0 | C13: =COUNTIFS(MASTER_TC!C:C,A13,MASTER_TC!K:K,"PASS") -> 0 | D13: =COUNTIFS(MASTER_TC!C:C,A13,MASTER_TC!K:K,"FAIL") -> 0 | E13: =COUNTIFS(MASTER_TC!C:C,A13,MASTER_TC!K:K,"BLOCKED") -> 0 | F13: =IF(B13=0,0,C13/B13) -> 0
